Workbook

Sheet Clientes
A2: ID cliente | B2: Tipo de documento | C2: Número de documento | D2: Nombre completo / Razón social | E2: Teléfono | F2: Correo electrónico | G2: Ciudad | H2: Dirección | I2: Fecha de registro | J2: Fecha de última actualización | K2: Estado de actualización | L2: Responsable de la actualización | M2: Observaciones | N2: Productos | O2: Score crediticio
A3: C-0001 | B3: CC | C3: 1090825067 | D3: Maria Fernanda Cardenas Suarez | F3: maria.fernanda32@example.com | G3: Ibague | H3: Transversal 5 # 12-28 | I3: 45552.583 | J3: 45851.672 | K3: Actualizado | L3: Asesor comercial | M3: Datos confirmados | N3: Fondo de inversion colectiva, Pencion obligatoria, Cesantias | O3: 803
A4: C-0002 | B4: NIT | C4: 900000002-0 | D4: Agroindustrias del Norte S.A.S. | E4: +573945256116 | F4: agroindustrias.del29@empresa.com.co | G4: Villavicencio | H4: Transversal 44A # 20-28 | I4: 45702.583 | J4: 45830.672 | K4: Pendiente de actualizar | L4: Backoffice | M4: Programado seguimiento telefonico | N4: Pencion obligatoria | O4: 823
A5: C-1000 | B5: NIT | C5: 1090000100 | D5: Andres Cruz | F5: andres.cruz54@example.com | G5: Medellin | H5: Calle 111 #27-4 | I5: 45551.583 | J5: 45850.672 | K5: ACTUALIZADO | L5: Asesor comercial | N5: Pension obligatoria, Fondo de inversion colectiva | O5: 700
A6: C-1001 | B6: CE | C6: 1090000101 | D6: Mariana Hernandez | E6: +573552669649 | F6: mariana.hernandez22@example.com | G6: Popayan | H6: Calle 92 #18-30 | I6: 45567.583 | J6: 45783.672 | K6: ACTUALIZADO | L6: Gerente de cuenta | M6: Contacto telefonico | N6: Pension voluntaria, Seguro de vida | O6: 820
A7: C-1002 | B7: CC | C7: 1090000102 | D7: Rosa Ramirez | E7: +573776988666 | F7: rosa.ramirez30@example.com | G7: Villavicencio | H7: Calle 109 #45-53 | I7: 45582.583 | J7: 45906.672 | K7: ACTUALIZADO | L7: Asesor comercial | M7: Datos confirmados | N7: Pension obligatoria, Cesantias, Fondo de inversion colectiva | O7: 585
A8: C-1003 | B8: PASAPORTE | C8: 1090000103 | D8: Roberto Cruz | E8: +573883981849 | F8: roberto.cruz8@example.com | G8: Manizales | H8: Calle 139 #34-33 | I8: 45713.583 | J8: 45862.672 | K8: ACTUALIZADO | L8: Backoffice | M8: Contacto telefonico | N8: Pension voluntaria | O8: 730
A9: C-1004 | B9: PASAPORTE | C9: 1090000104 | D9: Diego Vargas | F9: diego.vargas7@example.com | G9: Pasto | H9: Calle 94 #4-51 | I9: 45598.583 | J9: 45777.672 | K9: ACTUALIZADO | L9: Asesor comercial | M9: Datos confirmados | N9: Cesantias, Pension voluntaria, Seguro de vida | O9: 526
A10: C-1005 | B10: CC | C10: 1090000105 | D10: Patricia Moreno | E10: +573803699008 | F10: patricia.moreno70@example.com | G10: Pereira | H10: Calle 135 #19-21 | I10: 45682.583 | J10: 45828.672 | K10: ACTUALIZADO | L10: Backoffice | M10: Pendiente verificacion | N10: Cesantias, Seguro de vida | O10: 667
A11: C-1006 | B11: CE | C11: 1090000106 | D11: Mariana Castillo | E11: +573580188026 | F11: mariana.castillo33@example.com | G11: Santa Marta | H11: Calle 44 #20-60 | I11: 45673.583 | J11: 45875.672 | K11: ACTUALIZADO | L11: Asesor comercial | M11: Contacto telefonico | N11: Cesantias | O11: 506
A12: C-1007 | B12: CE | C12: 1090000107 | D12: Andres Martinez | F12: andres.martinez20@example.com | G12: Villavicencio | H12: Calle 122 #36-66 | I12: 45843.583 | J12: 45848.672 | K12: ACTUALIZADO | L12: Asesor comercial | M12: Pendiente verificacion | N12: Fondo de inversion colectiva, Pension obligatoria, Pension voluntaria | O12: 847
A13: C-1008 | B13: CE | C13: 1090000108 | D13: Fernando Gutierrez | E13: +573907726288 | F13: fernando.gutierrez57@example.com | G13: Santa Marta | H13: Calle 27 #43-13 | I13: 45712.583 | J13: 45892.672 | K13: ACTUALIZADO | L13: Gerente de cuenta | N13: Cesantias, Seguro de vida, Pension voluntaria | O13: 697
A14: C-1009 | B14: CE | C14: 1090000109 | D14: Maria Vargas | F14: maria.vargas65@example.com | G14: Cucuta | H14: Calle 47 #11-16 | I14: 45608.583 | J14: 45872.672 | K14: ACTUALIZADO | L14: Gerente de cuenta | M14: Contacto telefonico | N14: Fondo de inversion colectiva, Seguro de vida | O14: 761
A15: C-1010 | B15: CE | C15: 1090000110 | D15: Silvia Torres | E15: +573374436324 | F15: silvia.torres33@example.com | G15: Bogota | H15: Calle 40 #38-74 | I15: 45899.583 | J15: 45836.672 | K15: ACTUALIZADO | L15: Backoffice | M15: Datos confirmados | N15: Cesantias, Pension obligatoria, Seguro de vida | O15: 673
A16: C-1011 | B16: CC | C16: 1090000111 | D16: Silvia Gutierrez | F16: silvia.gutierrez76@example.com | G16: Pasto | H16: Calle 96 #9-4 | I16: 45865.583 | J16: 46263.672 | K16: ACTUALIZADO | L16: Backoffice | M16: Datos confirmados | N16: Cesantias, Seguro de vida | O16: 561
A17: C-1012 | B17: NIT | C17: 1090000112 | D17: Diego Sanchez | E17: +573280686300 | F17: diego.sanchez74@example.com | G17: Ibague | H17: Calle 13 #1-39 | I17: 45832.583 | J17: 46274.672 | K17: ACTUALIZADO | L17: Asesor comercial | M17: Pendiente verificacion | N17: Seguro de vida, Fondo de inversion colectiva, Cesantias | O17: 821
A18: C-1013 | B18: NIT | C18: 1090000113 | D18: Patricia Vargas | F18: patricia.vargas98@example.com | G18: Pereira | H18: Calle 119 #6-21 | I18: 45823.583 | J18: 46268.672 | K18: ACTUALIZADO | L18: Asesor comercial | N18: Pension voluntaria, Seguro de vida, Cesantias | O18: 543
A19: C-1014 | B19: CE | C19: 1090000114 | D19: Carlos Rodriguez | F19: carlos.rodriguez54@example.com | G19: Bucaramanga | H19: Calle 31 #46-13 | I19: 45594.583 | J19: 46269.672 | K19: ACTUALIZADO | L19: Asesor comercial | M19: Pendiente verificacion | N19: Pension obligatoria, Cesantias, Pension voluntaria | O19: 751
A20: C-1015 | B20: CC | C20: 1090000115 | D20: Fernando Lopez | F20: fernando.lopez84@example.com | G20: Medellin | H20: Calle 97 #38-73 | I20: 45770.583 | J20: 46267.672 | K20: ACTUALIZADO | L20: Asesor comercial | M20: Pendiente verificacion | N20: Cesantias | O20: 762
A21: C-1016 | B21: CC | C21: 1090000116 | D21: Silvia Torres | F21: silvia.torres41@example.com | G21: Cartagena | H21: Calle 43 #37-56 | I21: 45577.583 | J21: 46261.672 | K21: ACTUALIZADO | L21: Backoffice | M21: Contacto telefonico | N21: Pension obligatoria | O21: 652
A22: C-1017 | B22: CC | C22: 1090000117 | D22: Silvia Torres | E22: +573136815739 | F22: silvia.torres25@example.com | G22: Popayan | H22: Calle 113 #27-13 | I22: 45873.583 | J22: 46265.672 | K22: ACTUALIZADO | L22: Asesor comercial | M22: Datos confirmados | N22: Cesantias | O22: 611
A23: C-1018 | B23: CE | C23: 1090000118 | D23: Fernando Rodriguez | E23: +573943969877 | F23: fernando.rodriguez9@example.com | G23: Pereira | H23: Calle 85 #35-67 | I23: 45777.583 | J23: 46253.672 | K23: ACTUALIZADO | L23: Asesor comercial | M23: Contacto telefonico | N23: Pension voluntaria, Seguro de vida | O23: 647
A24: C-1019 | B24: CE | C24: 1090000119 | D24: Juan Castillo | E24: +573942712377 | F24: juan.castillo11@example.com | G24: Bogota | H24: Calle 106 #16-81 | I24: 45615.583 | J24: 46263.672 | K24: ACTUALIZADO | L24: Backoffice | M24: Datos confirmados | N24: Fondo de inversion colectiva, Pension obligatoria | O24: 469
A25: C-1020 | B25: NIT | C25: 1090000120 | D25: Diego Sanchez | F25: diego.sanchez51@example.com | G25: Medellin | H25: Calle 140 #32-93 | I25: 45717.583 | J25: 46264.672 | K25: ACTUALIZADO | L25: Backoffice | M25: Datos confirmados | N25: Fondo de inversion colectiva | O25: 494
A26: C-1021 | B26: CE | C26: 1090000121 | D26: Roberto Dominguez | F26: roberto.dominguez18@example.com | G26: Armenia | H26: Calle 18 #5-72 | I26: 45659.583 | J26: 46254.672 | K26: ACTUALIZADO | L26: Backoffice | N26: Cesantias, Pension obligatoria, Fondo de inversion colectiva | O26: 638
A27: C-1022 | B27: CE | C27: 1090000122 | D27: Andres Hernandez | E27: +573152611501 | F27: andres.hernandez79@example.com | G27: Medellin | H27: Calle 55 #3-45 | I27: 45713.583 | J27: 46269.672 | K27: ACTUALIZADO | L27: Backoffice | N27: Cesantias | O27: 849
A28: C-1023 | B28: CE | C28: 1090000123 | D28: Fernando Lopez | F28: fernando.lopez77@example.com | G28: Santa Marta | H28: Calle 102 #37-93 | I28: 45608.583 | J28: 46248.672 | K28: ACTUALIZADO | L28: Asesor comercial | M28: Datos confirmados | N28: Fondo de inversion colectiva, Cesantias | O28: 843
A29: C-1024 | B29: PASAPORTE | C29: 1090000124 | D29: Silvia Gutierrez | E29: +573970443844 | F29: silvia.gutierrez40@example.com | G29: Cali | H29: Calle 98 #35-69 | I29: 45591.583 | J29: 46267.672 | K29: ACTUALIZADO | L29: Gerente de cuenta | M29: Datos confirmados | N29: Pension obligatoria | O29: 629
A30: C-1025 | B30: NIT | C30: 1090000125 | D30: Ana Vargas | F30: ana.vargas93@example.com | G30: Villavicencio | H30: Calle 122 #24-17 | I30: 45550.583 | J30: 46255.672 | K30: ACTUALIZADO | L30: Backoffice | M30: Contacto telefonico | N30: Pension obligatoria, Fondo de inversion colectiva | O30: 599
A31: C-1026 | B31: CE | C31: 1090000126 | D31: Sandra Ramirez | F31: sandra.ramirez42@example.com | G31: Pasto | H31: Calle 79 #10-72 | I31: 45888.583 | J31: 46255.672 | K31: ACTUALIZADO | L31: Backoffice | N31: Pension voluntaria, Cesantias | O31: 753
A32: C-1027 | B32: NIT | C32: 1090000127 | D32: Miguel Cruz | F32: miguel.cruz68@example.com | G32: Armenia | H32: Calle 80 #15-15 | I32: 45607.583 | J32: 46263.672 | K32: ACTUALIZADO | L32: Gerente de cuenta | N32: Cesantias | O32: 846
A33: C-1028 | B33: NIT | C33: 1090000128 | D33: Juan Rodriguez | F33: juan.rodriguez62@example.com | G33: Armenia | H33: Calle 111 #43-95 | I33: 45719.583 | J33: 46275.672 | K33: ACTUALIZADO | L33: Gerente de cuenta | M33: Datos confirmados | N33: Fondo de inversion colectiva, Seguro de vida, Pension voluntaria | O33: 830
A34: C-1029 | B34: NIT | C34: 1090000129 | D34: Fernando Dominguez | E34: +573703684212 | F34: fernando.dominguez3@example.com | G34: Santa Marta | H34: Calle 47 #17-65 | I34: 45827.583 | J34: 46265.672 | K34: ACTUALIZADO | L34: Gerente de cuenta | M34: Pendiente verificacion | N34: Seguro de vida, Pension obligatoria, Cesantias | O34: 508
A35: C-1030 | B35: NIT | C35: 1090000130 | D35: Diego Martinez | E35: +573261525577 | F35: diego.martinez74@example.com | G35: Popayan | H35: Calle 27 #5-65 | I35: 45574.583 | J35: 46267.672 | K35: PENDIENTE | L35: Gerente de cuenta | M35: Contacto telefonico | N35: Pension voluntaria | O35: 543
A36: C-1031 | B36: CC | C36: 1090000131 | D36: Fernando Rodriguez | E36: +573512885949 | F36: fernando.rodriguez74@example.com | G36: Bucaramanga | H36: Calle 24 #49-7 | I36: 45823.583 | J36: 46250.672 | K36: =IF($A34="","",IF($J34="","Sin fecha",IF(TODAY()<=EDATE($J34,12),"Actualizado",IF(TODAY()<=EDATE($J34,15),"Pendiente de actualizar","Vencido")))) | L36: Backoffice | N36: Pension obligatoria, Cesantias, Fondo de inversion colectiva | O36: 819
A37: C-1032 | B37: CC | C37: 1090000132 | D37: Silvia Perez | E37: +573762882283 | F37: silvia.perez55@example.com | G37: Pereira | H37: Calle 14 #17-1 | I37: 45820.583 | J37: 46252.672 | K37: =IF($A35="","",IF($J35="","Sin fecha",IF(TODAY()<=EDATE($J35,12),"Actualizado",IF(TODAY()<=EDATE($J35,15),"Pendiente de actualizar","Vencido")))) | L37: Backoffice | M37: Pendiente verificacion | N37: Fondo de inversion colectiva, Seguro de vida | O37: 800
A38: C-1033 | B38: CC | C38: 1090000133 | D38: Juan Sanchez | F38: juan.sanchez37@example.com | G38: Popayan | H38: Calle 25 #21-61 | I38: 45803.583 | J38: 46249.672 | K38: =IF($A36="","",IF($J36="","Sin fecha",IF(TODAY()<=EDATE($J36,12),"Actualizado",IF(TODAY()<=EDATE($J36,15),"Pendiente de actualizar","Vencido")))) | L38: Gerente de cuenta | M38: Contacto telefonico | N38: Seguro de vida | O38: 727
A39: C-1034 | B39: CE | C39: 1090000134 | D39: Maria Ramirez | F39: maria.ramirez95@example.com | G39: Manizales | H39: Calle 129 #21-35 | I39: 45693.583 | J39: 46274.672 | K39: =IF($A37="","",IF($J37="","Sin fecha",IF(TODAY()<=EDATE($J37,12),"Actualizado",IF(TODAY()<=EDATE($J37,15),"Pendiente de actualizar","Vencido")))) | L39: Gerente de cuenta | M39: Datos confirmados | N39: Cesantias, Pension voluntaria | O39: 680
A40: C-1035 | B40: CC | C40: 1090000135 | D40: Sandra Sanchez | F40: sandra.sanchez80@example.com | G40: Armenia | H40: Calle 42 #12-5 | I40: 45743.583 | J40: 46251.672 | K40: =IF($A38="","",IF($J38="","Sin fecha",IF(TODAY()<=EDATE($J38,12),"Actualizado",IF(TODAY()<=EDATE($J38,15),"Pendiente de actualizar","Vencido")))) | L40: Gerente de cuenta | N40: Pension obligatoria, Seguro de vida | O40: 454
A41: C-1036 | B41: PASAPORTE | C41: 1090000136 | D41: Carlos Garcia | F41: carlos.garcia6@example.com | G41: Medellin | H41: Calle 82 #29-36 | I41: 45616.583 | J41: 46250.672 | K41: =IF($A39="","",IF($J39="","Sin fecha",IF(TODAY()<=EDATE($J39,12),"Actualizado",IF(TODAY()<=EDATE($J39,15),"Pendiente de actualizar","Vencido")))) | L41: Gerente de cuenta | M41: Pendiente verificacion | N41: Pension obligatoria | O41: 705
...

Sheet Resumen
A1: Resumen de actualización de datos
A2: Estos indicadores se recalculan automáticamente a partir de la hoja "Clientes".
A4: Total de clientes | B4: =COUNTIF('Clientes'!$A$3:$A$302,"<>")
A5: Clientes actualizados | B5: =COUNTIF('Clientes'!$K$3:$K$302,"Actualizado")
A6: Clientes pendientes de actualizar | B6: =COUNTIF('Clientes'!$K$3:$K$302,"Pendiente de actualizar")
A7: Clientes vencidos | B7: =COUNTIF('Clientes'!$K$3:$K$302,"Vencido")
A8: Porcentaje de actualización | B8: =IFERROR(B5/B4,0)
A9: Score crediticio promedio | B9: =IFERROR(AVERAGE('Clientes'!$O$3:$O$302),0)

Sheet Listas
A1: Tipo de documento | B1: Responsable de la actualización | C1: Catálogo de productos (referencia)
A2: CC | B2: Cliente (autogestión) | C2: Pensión obligatoria
A3: CE | B3: Asesor comercial | C3: Pensión voluntaria
A4: NIT | B4: Backoffice | C4: Cesantías
A5: Pasaporte | B5: Call center | C5: Seguro de vida
A6: Tarjeta de identidad | B6: Otro | C6: Fondo de inversión colectiva
